Workbook
Name StatusOptions_33: [1]Hidden_Options_33!$A$1:$A$2

Sheet 职能部门ERP操作汇总
A1: 序号 | B1: 部门 | C1: 部门总人数 | D1: 参与人数 | E1: 发起流程总数 | F1: 审批流程总数 | G1: 处理时间（分钟） | H1: 驳回次数 | I1: 有效评论次数
A2: =ROW()-1 -> 1 | B2: HSE部 | C2: =COUNTIFS(职能部门人员台账!A:A,B2) -> 6 | D2: 4 | E2: =SUMIFS(职能部门人员ERP操作!E:E,职能部门人员ERP操作!A:A,B2,职能部门人员ERP操作!D:D,"发起者") -> 65 | F2: =SUMIFS(职能部门人员ERP操作!E:E,职能部门人员ERP操作!A:A,B2,职能部门人员ERP操作!D:D,"*审批*") -> 4230 | G2: =SUMIFS(职能部门人员ERP操作!F:F,职能部门人员ERP操作!A:A,B2) -> 1946295 | H2: =SUMIFS(职能部门人员ERP操作!G:G,职能部门人员ERP操作!A:A,B2) -> 28 | I2: =SUMIFS(职能部门人员ERP操作!H:H,职能部门人员ERP操作!A:A,B2) -> 40
A3: =ROW()-1 -> 2 | B3: 待岗人员 | C3: =COUNTIFS(职能部门人员台账!A:A,B3) -> 15 | D3: 6 | E3: =SUMIFS(职能部门人员ERP操作!E:E,职能部门人员ERP操作!A:A,B3,职能部门人员ERP操作!D:D,"发起者") -> 121 | F3: =SUMIFS(职能部门人员ERP操作!E:E,职能部门人员ERP操作!A:A,B3,职能部门人员ERP操作!D:D,"*审批*") -> 965 | G3: =SUMIFS(职能部门人员ERP操作!F:F,职能部门人员ERP操作!A:A,B3) -> 913705 | H3: =SUMIFS(职能部门人员ERP操作!G:G,职能部门人员ERP操作!A:A,B3) -> 1 | I3: =SUMIFS(职能部门人员ERP操作!H:H,职能部门人员ERP操作!A:A,B3) -> 2
A4: =ROW()-1 -> 3 | B4: 公司领导 | C4: =COUNTIFS(职能部门人员台账!A:A,B4) -> 10 | D4: 10 | E4: =SUMIFS(职能部门人员ERP操作!E:E,职能部门人员ERP操作!A:A,B4,职能部门人员ERP操作!D:D,"发起者") -> 44 | F4: =SUMIFS(职能部门人员ERP操作!E:E,职能部门人员ERP操作!A:A,B4,职能部门人员ERP操作!D:D,"*审批*") -> 40026 | G4: =SUMIFS(职能部门人员ERP操作!F:F,职能部门人员ERP操作!A:A,B4) -> 25164981 | H4: =SUMIFS(职能部门人员ERP操作!G:G,职能部门人员ERP操作!A:A,B4) -> 721 | I4: =SUMIFS(职能部门人员ERP操作!H:H,职能部门人员ERP操作!A:A,B4) -> 1011
A5: =ROW()-1 -> 4 | B5: 海外事业部 | C5: =COUNTIFS(职能部门人员台账!A:A,B5) -> 10 | D5: 10 | E5: =SUMIFS(职能部门人员ERP操作!E:E,职能部门人员ERP操作!A:A,B5,职能部门人员ERP操作!D:D,"发起者") -> 61 | F5: =SUMIFS(职能部门人员ERP操作!E:E,职能部门人员ERP操作!A:A,B5,职能部门人员ERP操作!D:D,"*审批*") -> 1929 | G5: =SUMIFS(职能部门人员ERP操作!F:F,职能部门人员ERP操作!A:A,B5) -> 565947 | H5: =SUMIFS(职能部门人员ERP操作!G:G,职能部门人员ERP操作!A:A,B5) -> 11 | I5: =SUMIFS(职能部门人员ERP操作!H:H,职能部门人员ERP操作!A:A,B5) -> 34
A6: =ROW()-1 -> 5 | B6: 合同管理部 | C6: =COUNTIFS(职能部门人员台账!A:A,B6) -> 8 | D6: 7 | E6: =SUMIFS(职能部门人员ERP操作!E:E,职能部门人员ERP操作!A:A,B6,职能部门人员ERP操作!D:D,"发起者") -> 2837 | F6: =SUMIFS(职能部门人员ERP操作!E:E,职能部门人员ERP操作!A:A,B6,职能部门人员ERP操作!D:D,"*审批*") -> 26889 | G6: =SUMIFS(职能部门人员ERP操作!F:F,职能部门人员ERP操作!A:A,B6) -> 73769892 | H6: =SUMIFS(职能部门人员ERP操作!G:G,职能部门人员ERP操作!A:A,B6) -> 1427 | I6: =SUMIFS(职能部门人员ERP操作!H:H,职能部门人员ERP操作!A:A,B6) -> 8501
A7: =ROW()-1 -> 6 | B7: 技术质量部 | C7: =COUNTIFS(职能部门人员台账!A:A,B7) -> 10 | D7: 9 | E7: =SUMIFS(职能部门人员ERP操作!E:E,职能部门人员ERP操作!A:A,B7,职能部门人员ERP操作!D:D,"发起者") -> 48 | F7: =SUMIFS(职能部门人员ERP操作!E:E,职能部门人员ERP操作!A:A,B7,职能部门人员ERP操作!D:D,"*审批*") -> 3544 | G7: =SUMIFS(职能部门人员ERP操作!F:F,职能部门人员ERP操作!A:A,B7) -> 1752929 | H7: =SUMIFS(职能部门人员ERP操作!G:G,职能部门人员ERP操作!A:A,B7) -> 330 | I7: =SUMIFS(职能部门人员ERP操作!H:H,职能部门人员ERP操作!A:A,B7) -> 407
A8: =ROW()-1 -> 7 | B8: 技术中心 | C8: =COUNTIFS(职能部门人员台账!A:A,B8) -> 23 | D8: 14 | E8: =SUMIFS(职能部门人员ERP操作!E:E,职能部门人员ERP操作!A:A,B8,职能部门人员ERP操作!D:D,"发起者") -> 656 | F8: =SUMIFS(职能部门人员ERP操作!E:E,职能部门人员ERP操作!A:A,B8,职能部门人员ERP操作!D:D,"*审批*") -> 4272 | G8: =SUMIFS(职能部门人员ERP操作!F:F,职能部门人员ERP操作!A:A,B8) -> 21581216 | H8: =SUMIFS(职能部门人员ERP操作!G:G,职能部门人员ERP操作!A:A,B8) -> 174 | I8: =SUMIFS(职能部门人员ERP操作!H:H,职能部门人员ERP操作!A:A,B8) -> 529
A9: =ROW()-1 -> 8 | B9: 人力资源部 | C9: =COUNTIFS(职能部门人员台账!A:A,B9) -> 7 | D9: 7 | E9: =SUMIFS(职能部门人员ERP操作!E:E,职能部门人员ERP操作!A:A,B9,职能部门人员ERP操作!D:D,"发起者") -> 484 | F9: =SUMIFS(职能部门人员ERP操作!E:E,职能部门人员ERP操作!A:A,B9,职能部门人员ERP操作!D:D,"*审批*") -> 8890 | G9: =SUMIFS(职能部门人员ERP操作!F:F,职能部门人员ERP操作!A:A,B9) -> 7670723 | H9: =SUMIFS(职能部门人员ERP操作!G:G,职能部门人员ERP操作!A:A,B9) -> 233 | I9: =SUMIFS(职能部门人员ERP操作!H:H,职能部门人员ERP操作!A:A,B9) -> 717
A10: =ROW()-1 -> 9 | B10: 审计部 | C10: =COUNTIFS(职能部门人员台账!A:A,B10) -> 2 | D10: 1 | E10: =SUMIFS(职能部门人员ERP操作!E:E,职能部门人员ERP操作!A:A,B10,职能部门人员ERP操作!D:D,"发起者") -> 61 | F10: =SUMIFS(职能部门人员ERP操作!E:E,职能部门人员ERP操作!A:A,B10,职能部门人员ERP操作!D:D,"*审批*") -> 9704 | G10: =SUMIFS(职能部门人员ERP操作!F:F,职能部门人员ERP操作!A:A,B10) -> 3089524 | H10: =SUMIFS(职能部门人员ERP操作!G:G,职能部门人员ERP操作!A:A,B10) -> 178 | I10: =SUMIFS(职能部门人员ERP操作!H:H,职能部门人员ERP操作!A:A,B10) -> 379
A11: =ROW()-1 -> 10 | B11: 市场开发部 | C11: =COUNTIFS(职能部门人员台账!A:A,B11) -> 22 | D11: 14 | E11: =SUMIFS(职能部门人员ERP操作!E:E,职能部门人员ERP操作!A:A,B11,职能部门人员ERP操作!D:D,"发起者") -> 252 | F11: =SUMIFS(职能部门人员ERP操作!E:E,职能部门人员ERP操作!A:A,B11,职能部门人员ERP操作!D:D,"*审批*") -> 12115 | G11: =SUMIFS(职能部门人员ERP操作!F:F,职能部门人员ERP操作!A:A,B11) -> 3537751 | H11: =SUMIFS(职能部门人员ERP操作!G:G,职能部门人员ERP操作!A:A,B11) -> 84 | I11: =SUMIFS(职能部门人员ERP操作!H:H,职能部门人员ERP操作!A:A,B11) -> 154
A12: =ROW()-1 -> 11 | B12: 物资部 | C12: =COUNTIFS(职能部门人员台账!A:A,B12) -> 11 | D12: 11 | E12: =SUMIFS(职能部门人员ERP操作!E:E,职能部门人员ERP操作!A:A,B12,职能部门人员ERP操作!D:D,"发起者") -> 738 | F12: =SUMIFS(职能部门人员ERP操作!E:E,职能部门人员ERP操作!A:A,B12,职能部门人员ERP操作!D:D,"*审批*") -> 18608 | G12: =SUMIFS(职能部门人员ERP操作!F:F,职能部门人员ERP操作!A:A,B12) -> 10887835 | H12: =SUMIFS(职能部门人员ERP操作!G:G,职能部门人员ERP操作!A:A,B12) -> 1178 | I12: =SUMIFS(职能部门人员ERP操作!H:H,职能部门人员ERP操作!A:A,B12) -> 1745
A13: =ROW()-1 -> 12 | B13: 项目管理公司 | C13: =COUNTIFS(职能部门人员台账!A:A,B13) -> 30 | D13: 22 | E13: =SUMIFS(职能部门人员ERP操作!E:E,职能部门人员ERP操作!A:A,B13,职能部门人员ERP操作!D:D,"发起者") -> 885 | F13: =SUMIFS(职能部门人员ERP操作!E:E,职能部门人员ERP操作!A:A,B13,职能部门人员ERP操作!D:D,"*审批*") -> 14424 | G13: =SUMIFS(职能部门人员ERP操作!F:F,职能部门人员ERP操作!A:A,B13) -> 5310149 | H13: =SUMIFS(职能部门人员ERP操作!G:G,职能部门人员ERP操作!A:A,B13) -> 621 | I13: =SUMIFS(职能部门人员ERP操作!H:H,职能部门人员ERP操作!A:A,B13) -> 1261
... A16: =ROW()-1 -> 15 | B16: 综合办公室 | C16: =COUNTIFS(职能部门人员台账!A:A,B16) -> 20 | D16: 10 | E16: =SUMIFS(职能部门人员ERP操作!E:E,职能部门人员ERP操作!A:A,B16,职能部门人员ERP操作!D:D,"发起者") -> 207 | F16: =SUMIFS(职能部门人员ERP操作!E:E,职能部门人员ERP操作!A:A,B16,职能部门人员ERP操作!D:D,"*审批*") -> 10855 | G16: =SUMIFS(职能部门人员ERP操作!F:F,职能部门人员ERP操作!A:A,B16) -> 144947571 | H16: =SUMIFS(职能部门人员ERP操作!G:G,职能部门人员ERP操作!A:A,B16) -> 70 | I16: =SUMIFS(职能部门人员ERP操作!H:H,职能部门人员ERP操作!A:A,B16) -> 387
B17: 合计 | C17: =SUM(C2:C16) -> 208 | D17: =SUM(D2:D16) -> 159 | E17: =SUM(E2:E16) -> 10294 | F17: =SUM(F2:F16) -> 296177 | G17: =SUM(G2:G16) -> 735734759 | H17: =SUM(H2:H16) -> 8243 | I17: =SUM(I2:I16) -> 20734

Sheet 职能部门人员ERP操作
A1: 部门 | B1: 人员名称 | C1: 是否机关 | D1: 参与类型 | E1: 参与流程数量 | F1: 处理时间（分钟） | G1: 驳回次数 | H1: 有效评论次数
A2: HSE部 | B2: 韩邢轩 | C2: 公司机关 | D2: 参与审批者 | E2: 24 | F2: 6374 | G2: 0 | H2: 0
A3: HSE部 | B3: 韩邢轩 | C3: 公司机关 | D3: 发起者 | E3: 5 | F3: 588 | G3: 0 | H3: 1
A4: HSE部 | B4: 刘少兵 | C4: 公司机关 | D4: 参与审批者 | E4: 3405 | F4: 1331324 | G4: 21 | H4: 28
A5: HSE部 | B5: 刘少兵 | C5: 公司机关 | D5: 发起者 | E5: 21 | F5: 1219 | G5: 0 | H5: 0
A6: HSE部 | B6: 薛慧 | C6: 公司机关 | D6: 参与审批者 | E6: 653 | F6: 511612 | G6: 7 | H6: 10
A7: HSE部 | B7: 薛慧 | C7: 公司机关 | D7: 发起者 | E7: 37 | F7: 23671 | G7: 0 | H7: 1
A8: HSE部 | B8: 张衡博 | C8: 公司机关 | D8: 参与审批者 | E8: 148 | F8: 63111 | G8: 0 | H8: 0
A9: HSE部 | B9: 张衡博 | C9: 公司机关 | D9: 发起者 | E9: 2 | F9: 8396 | G9: 0 | H9: 0
A10: 待岗人员 | B10: 何永欣 | C10: 公司机关 | D10: 参与审批者 | E10: 2 | F10: 179 | G10: 0 | H10: 0
A11: 待岗人员 | B11: 梁鑫 | C11: 公司机关 | D11: 参与审批者 | E11: 345 | F11: 5961 | G11: 0 | H11: 0
A12: 待岗人员 | B12: 梁鑫 | C12: 公司机关 | D12: 发起者 | E12: 100 | F12: 9 | G12: 0 | H12: 0
A13: 待岗人员 | B13: 沙永忠 | C13: 公司机关 | D13: 参与审批者 | E13: 27 | F13: 23557 | G13: 0 | H13: 0
... A275: 综合办公室 | B275: 赵乐 | C275: 公司机关 | D275: 发起者 | E275: 2 | F275: 28 | G275: 0 | H275: 0

Sheet 职能部门人员台账
A1: 部门 | B1: 姓名 | C1: 性别 | D1: 身份证 | E1: 职位 | F1: 出生日期 | G1: 年龄 | H1: 参加工作时间 | I1: 到本单位时间 | J1: 人员类别 | K1: 籍贯 | L1: 联系电话 | M1: 学历 | N1: 专业 | O1: 毕业学校 | P1: 毕业时间 | Q1: 出资人代表标识 | R1: 员工身份 | S1: 政治面貌 | T1: 创建人 | U1: 拥有者(必填) | V1: 所属部门(必填) | W1: 创建时间 | X1: 修改时间 | Y1: 数据状态 | Z1: 单位 | AA1: 家庭住址 | AB1: 是否完成提交-2025 | AC1: 辅助控件-是 | AD1: 群众测评是否完成提交-2025 | AE1: 高层领导 | AF1: 部门-原始 | AG1: ERP人员台账id | AH1: 个人是/否 | AI1: 是否在职 | AJ1: ERP人员编号 | AK1: 在职状态
A2: 信息化中心 | B2: 杨荣康 | C2: 男 | D2: 32118319970712481X | E2: 技术助理(一) | F2: 1997-07 | G2: 29 | H2: 2019-09-01 | I2: 2026-01-01 | J2: 专业技术 | K2: 江苏省句容市 | L2: 18173575050 | M2: 本科 | N2: 其他 | O2: 南京理工大学泰州学院 | P2: 2019-06-30 | R2: 干部 | S2: 群众 | T2: 陈苏宁 | U2: 陈苏宁 | V2: 管理创新研究室 | W2: 2026-05-07 14:36:41 | X2: 2026-05-07 14:36:41 | Y2: 已生效 | Z2: 南京南化建设有限公司 | AA2: 江苏省镇江市句容市 | AC2: 是 | AF2: 信息化中心 | AH2: 否 | AI2: 是 | AK2: 在职
A3: 技术中心 | B3: 杨莉娟 | C3: 女 | D3: 340302199004160027 | E3: 技术助理(一) | F3: 1990-04 | G3: 36 | H3: 2013-11-01 | I3: 2026-03-09 | J3: 专业技术 | K3: 安徽蚌埠市 | L3: 17721022695 | M3: 本科 | O3: 武汉工程大学 | P3: 2013-06-30 | R3: 干部 | T3: 陈苏宁 | U3: 陈苏宁 | V3: 管理创新研究室 | W3: 2026-05-07 14:36:41 | X3: 2026-05-07 14:36:41 | Y3: 已生效 | Z3: 南京南化建设有限公司 | AA3: 南京市六合区山居花园兰苑7栋2002 | AC3: 是 | AF3: 技术中心 | AH3: 否 | AI3: 是 | AK3: 在职
A4: 综合办公室 | B4: 张明 | C4: 男 | D4: 320112196710290413 | E4: 辅助工种高级工 | F4: 1967-10 | G4: 58 | H4: 1985-12-01 | I4: 1985-12-01 | J4: 技能操作 | K4: 江苏省南京市 | L4: 15996454089 | M4: 技校 | N4: 铆工 | P4: 1983-07-01 | Q4: 股东 | R4: 工人 | S4: 群众 | T4: 陈苏宁 | U4: 陈苏宁 | V4: 管理创新研究室 | W4: 2025-12-26 16:53:23 | X4: 2026-03-23 14:36:53 | Y4: 已生效 | Z4: 南京南化建设有限公司 | AA4: 江苏省 南京市 六合区 大厂街道南京南化建设有限公司(慈善幸福路) | AB4: 是 | AC4: 是 | AD4: 是 | AF4: 经理办公室 | AG4: C13F5F4B-A964-3B2F-76CC-E3F0B1CEF939 | AH4: 否 | AJ4: 1985005 | AK4: 在职
A5: 公司领导 | B5: 武光 | C5: 男 | D5: 320112196004110410 | E5: 党委书记 | F5: 1960-04 | G5: 65 | H5: 1982-08-01 | I5: 1978-01-01 | J5: 经营管理 | M5: 本科 | N5: 化机 | O5: 江苏石油化工学院 | P5: 1982-07-01 | Q5: 股东 | R5: 干部 | S5: 党员 | T5: 陈苏宁 | U5: 陈苏宁 | V5: 管理创新研究室 | W5: 2025-12-26 16:53:23 | X5: 2026-05-07 10:32:13 | Y5: 已生效 | Z5: 南京南化建设有限公司 | AB5: 否 | AC5: 是 | AD5: 否 | AF5: 公司领导 | AG5: AA0EB73B-26D7-4E5B-BCFC-3C9F489C3E57 | AH5: 否 | AJ5: 1978008 | AK5: 在职
A6: 物资部 | B6: 王仁斌 | C6: 男 | D6: 320112196710260417 | E6: 主要工种高级工 | F6: 1967-10 | G6: 58 | H6: 1986-05-01 | I6: 1986-05-01 | J6: 技能操作 | K6: 江苏省 | L6: 13813914682 | M6: 初中 | N6: 电焊工 | Q6: 股东 | R6: 工人 | S6: 群众 | T6: 陈苏宁 | U6: 陈苏宁 | V6: 管理创新研究室 | W6: 2025-12-26 16:53:23 | X6: 2026-03-20 17:24:45 | Y6: 已生效 | Z6: 南京南化建设有限公司 | AA6: 江苏省 南京市 六合区 沿江工业开发区凤凰南路172号 | AB6: 是 | AC6: 是 | AD6: 是 | AF6: 物资部 | AG6: 19B050FE-4835-9B0E-87E1-1356F8563E45 | AH6: 否 | AJ6: 1986010 | AK6: 在职
A7: 综合办公室 | B7: 陈庆忠 | C7: 男 | D7: 320112196810060412 | E7: 主要工种高级工 | F7: 1968-10 | G7: 57 | H7: 1984-12-01 | I7: 1984-12-01 | J7: 技能操作 | K7: 江苏省 | L7: 13851877629 | M7: 初中 | N7: 电焊工 | P7: 1970-01-01 | Q7: 股东 | R7: 工人 | S7: 群众 | T7: 陈苏宁 | U7: 陈苏宁 | V7: 管理创新研究室 | W7: 2025-12-26 16:53:23 | X7: 2026-03-23 14:36:55 | Y7: 已生效 | Z7: 南京南化建设有限公司 | AA7: 江苏省 南京市 六合区 大厂街道南京南化建设有限公司(慈善幸福路) | AB7: 是 | AC7: 是 | AD7: 是 | AF7: 经理办公室 | AG7: DBD1B9FF-E20B-55E5-C496-9415951B9C57 | AH7: 否 | AJ7: 1984001 | AK7: 在职
A8: 综合办公室 | B8: 许聚宝 | C8: 男 | D8: 320112196911240412 | E8: 辅助工种高级工 | F8: 1969-11 | G8: 56 | H8: 1984-12-01 | I8: 1984-12-01 | J8: 技能操作 | K8: 天津市 | L8: 15951645179 | M8: 初中 | N8: 电焊工 | P8: 1970-01-01 | Q8: 股东 | R8: 工人 | S8: 群众 | T8: 陈苏宁 | U8: 陈苏宁 | V8: 管理创新研究室 | W8: 2025-12-26 16:53:23 | X8: 2026-03-23 14:36:57 | Y8: 已生效 | Z8: 南京南化建设有限公司 | AA8: 江苏省 南京市 六合区 | AB8: 是 | AC8: 是 | AD8: 是 | AF8: 经理办公室 | AG8: 21CADA49-CAA9-86AB-D73B-C266A70AB7C7 | AH8: 否 | AJ8: 1984018 | AK8: 在职
A9: 项目管理公司 | B9: 董家明 | C9: 男 | D9: 320112196603020418 | E9: 业务主办B | F9: 1966-03 | G9: 59 | H9: 1984-12-01 | I9: 1984-12-01 | J9: 专业技术 | L9: 13770816352 | M9: 初中 | N9: 安全员 | P9: 1981-06-30 | Q9: 股东 | R9: 干部 | S9: 群众 | T9: 陈苏宁 | U9: 陈苏宁 | V9: 管理创新研究室 | W9: 2025-12-26 16:53:23 | X9: 2026-03-23 14:36:58 | Y9: 已生效 | Z9: 南京南化建设有限公司 | AA9: 江苏省 南京市 六合区 杨庄北村16栋 | AB9: 是 | AC9: 是 | AD9: 是 | AF9: 合同管理部 | AG9: 0FFD246C-32CE-3289-3AD8-66B73CD2AA7E | AH9: 否 | AJ9: 1984003 | AK9: 在职
A10: 项目管理公司 | B10: 刘豪 | C10: 男 | D10: 320112196806160410 | E10: 中层正职(一类) | F10: 1968-06 | G10: 57 | H10: 1988-07-01 | I10: 1988-07-01 | J10: 经营管理 | L10: 13851588621 | M10: 本科 | N10: 化机 | O10: 江苏省自学考试中心 | P10: 2020-01-10 | Q10: 股东 | R10: 干部 | S10: 党员 | T10: 陈苏宁 | U10: 陈苏宁 | V10: 管理创新研究室 | W10: 2025-12-26 16:53:22 | X10: 2026-03-23 14:37:02 | Y10: 已生效 | Z10: 南京南化建设有限公司 | AA10: 江苏省 南京市 六合区 化建新一村49栋603 | AB10: 是 | AC10: 是 | AD10: 是 | AE10: 周小明 | AF10: 合同管理部 | AG10: 5CB6C770-6BA1-7C0C-B2C4-8A58B2FE8333 | AH10: 否 | AJ10: 1988007 | AK10: 在职
A11: 合同管理部 | B11: 倪铭琦 | C11: 男 | D11: 320112197208130478 | E11: 专业工程师 | F11: 1972-08 | G11: 53 | H11: 1989-08-01 | I11: 1989-08-01 | J11: 专业技术 | K11: 江苏省南京市六合区 | L11: 13951793059 | M11: 大专 | N11: 土建 | O11: 扬州大学 | P11: 2003-12-30 | Q11: 股东 | R11: 干部 | S11: 群众 | T11: 陈苏宁 | U11: 陈苏宁 | V11: 管理创新研究室 | W11: 2025-12-26 16:53:22 | X11: 2026-03-20 17:24:54 | Y11: 已生效 | Z11: 南京南化建设有限公司 | AA11: 江苏省 南京市 六合区 荣盛水景城摇光苑6-1001 | AB11: 是 | AC11: 是 | AD11: 是 | AF11: 合同管理部 | AG11: D5EA10A2-AC76-6347-41F4-2A281F55C01F | AH11: 否 | AJ11: 1989006 | AK11: 在职
A12: 资产财务部 | B12: 张海 | C12: 男 | D12: 320112196809180417 | E12: 业务主管 | F12: 1968-09 | G12: 57 | H12: 1987-07-01 | I12: 1987-07-01 | J12: 专业技术 | L12: 19850871279 | M12: 中专 | N12: 会计 | O12: 南京市职工中专学校 | P12: 1995-04-01 | Q12: 股东 | R12: 干部 | S12: 群众 | T12: 陈苏宁 | U12: 陈苏宁 | V12: 管理创新研究室 | W12: 2025-12-26 16:53:22 | X12: 2026-03-20 17:24:56 | Y12: 已生效 | Z12: 南京南化建设有限公司 | AA12: 江苏省 南京市 六合区 文承熙媛 | AB12: 是 | AC12: 是 | AD12: 否 | AF12: 资产财务部 | AG12: E92287F2-D61F-A0B8-99F8-24C761DECB82 | AH12: 否 | AJ12: 1987004 | AK12: 在职
A13: 待岗人员 | B13: 王卫 | C13: 男 | D13: 320112196911050416 | E13: 技术助理(一) | F13: 1969-11 | G13: 56 | H13: 1989-07-01 | I13: 1989-07-01 | J13: 专业技术 | K13: 山东省济南市市辖区 | L13: 18921412518 | M13: 大专 | N13: 仪表 | O13: 南京广播电视大学 | P13: 1993-07-01 | Q13: 股东 | R13: 干部 | S13: 群众 | T13: 陈苏宁 | U13: 陈苏宁 | V13: 管理创新研究室 | W13: 2025-12-26 16:53:22 | X13: 2026-03-20 17:24:57 | Y13: 已生效 | Z13: 南京南化建设有限公司 | AB13: 否 | AC13: 是 | AD13: 否 | AF13: 待岗人员 | AG13: E301D994-340B-9A96-7EC5-812DF236FABD | AH13: 否 | AJ13: 1989008 | AK13: 在职
A14: 物资部 | B14: 吴彪 | C14: 男 | D14: 320112197004040438 | E14: 中层副职(一类) | F14: 1970-04 | G14: 55 | H14: 1989-03-01 | I14: 1989-03-01 | J14: 经营管理 | K14: 上海市崇明县 | L14: 13912982650 | M14: 大专 | O14: 南京市广播电视大学 | P14: 1997-01-01 | Q14: 股东 | R14: 干部 | S14: 党员 | T14: 陈苏宁 | U14: 陈苏宁 | V14: 管理创新研究室 | W14: 2025-12-26 16:53:22 | X14: 2026-03-20 17:25:01 | Y14: 已生效 | Z14: 南京南化建设有限公司 | AA14: 江苏省 南京市 六合区 南京市沿江工业开发区化建新一村51幢304室 | AB14: 是 | AC14: 是 | AD14: 是 | AE14: 方向前 | AF14: 物资部 | AG14: 5D2F0701-6211-CB3B-9054-3401C623C358 | AH14: 否 | AJ14: 1989009 | AK14: 在职
A15: 公司领导 | B15: 邢振华 | C15: 男 | D15: 320112196603100434 | E15: 副总经理 | F15: 1966-03 | G15: 59 | H15: 1986-11-01 | I15: 1986-11-01 | J15: 经营管理 | L15: 13913357302 | M15: 中专 | N15: 化机 | O15: 淮南化学工程学校 | P15: 2023-10-12 | Q15: 股东 | R15: 干部 | S15: 群众 | T15: 陈苏宁 | U15: 陈苏宁 | V15: 管理创新研究室 | W15: 2025-12-26 16:53:22 | X15: 2026-05-07 10:32:13 | Y15: 已生效 | Z15: 南京南化建设有限公司 | AB15: 否 | AC15: 是 | AD15: 否 | AF15: 公司领导 | AG15: 0E584ECB-612C-DE95-7CC1-9E2A945E9FE7 | AH15: 否 | AJ15: 1986014 | AK15: 在职
A16: 项目管理公司 | B16: 常伟 | C16: 男 | D16: 320112196706280415 | E16: 中层副职(一类) | F16: 1967-06 | G16: 58 | H16: 1989-12-01 | I16: 1989-12-01 | J16: 经营管理 | L16: 13951981127 | M16: 大专 | N16: 化机 | O16: 东南大学 | P16: 1989-07-01 | Q16: 股东 | R16: 干部 | S16: 党员 | T16: 陈苏宁 | U16: 陈苏宁 | V16: 管理创新研究室 | W16: 2025-12-26 16:53:22 | X16: 2026-03-23 14:37:05 | Y16: 已生效 | Z16: 南京南化建设有限公司 | AA16: 江苏省 南京市 六合区 化建新一村 | AB16: 是 | AC16: 是 | AD16: 是 | AE16: 周小明 | AF16: 合同管理部 | AG16: A75398FD-18BE-BFBB-8B28-EFEF98FA596E | AH16: 否 | AJ16: 1989001 | AK16: 在职
A17: 市场开发部 | B17: 王培云 | C17: 女 | D17: 32011219710204044X | E17: 主管工程师 | F17: 1971-02 | G17: 54 | H17: 1989-07-01 | I17: 1989-07-01 | J17: 专业技术 | K17: 江苏省淮安市 | L17: 13851559136 | M17: 中专 | N17: 化机 | O17: 淮南化学工程学校 | P17: 1989-07-01 | Q17: 股东 | R17: 干部 | S17: 群众 | T17: 陈苏宁 | U17: 陈苏宁 | V17: 管理创新研究室 | W17: 2025-12-26 16:53:22 | X17: 2026-03-20 17:25:16 | Y17: 已生效 | Z17: 南京南化建设有限公司 | AA17: 江苏省 南京市 浦口区 金城丽景 | AB17: 是 | AC17: 是 | AD17: 是 | AF17: 市场开发部 | AG17: 3CEB880B-877C-44B5-290C-FE0F4FBCF0AD | AH17: 否 | AJ17: 1989007 | AK17: 在职
A18: 公司领导 | B18: 黄可中 | C18: 男 | D18: 310104196812160415 | E18: 副总经理 | F18: 1968-12 | G18: 57 | H18: 1990-07-01 | I18: 1990-07-01 | J18: 经营管理 | L18: 13851940998 | M18: 本科 | N18: 化机 | O18: 上海交通大学 | P18: 1990-07-01 | Q18: 股东 | R18: 干部 | S18: 群众 | T18: 陈苏宁 | U18: 陈苏宁 | V18: 管理创新研究室 | W18: 2025-12-26 16:53:22 | X18: 2026-03-20 17:25:16 | Y18: 已生效 | Z18: 南京南化建设有限公司 | AB18: 否 | AC18: 是 | AD18: 否 | AF18: 公司领导 | AG18: 5EB67C94-19A6-8B9A-1F3A-6D54FAAFAF45 | AH18: 否 | AJ18: 1990006 | AK18: 在职
A19: 资产财务部 | B19: 江必文 | C19: 男 | D19: 320112196804210410 | E19: 副总师 | F19: 1968-04 | G19: 57 | H19: 1988-12-01 | I19: 1988-12-01 | J19: 经营管理 | L19: 13951643244 | M19: 大专 | O19: 南京市电视大学 | P19: 1988-07-01 | Q19: 股东 | R19: 干部 | S19: 党员 | T19: 陈苏宁 | U19: 陈苏宁 | V19: 管理创新研究室 | W19: 2025-12-26 16:53:22 | X19: 2026-03-20 17:25:20 | Y19: 已生效 | Z19: 南京南化建设有限公司 | AA19: 江苏省 南京市 六合区 江北新区大厂街道杨庄北村16-505 | AB19: 是 | AC19: 是 | AD19: 是 | AE19: 王勇 | AF19: 资产财务部 | AG19: 6178C3C0-B750-DA3A-D35A-A8B535EB9B64 | AH19: 否 | AJ19: 1988003 | AK19: 在职
A20: 项目管理公司 | B20: 李玉生 | C20: 男 | D20: 32011219731020041X | E20: 副总师 | F20: 1973-10 | G20: 52 | H20: 1992-08-01 | I20: 1992-08-01 | J20: 经营管理 | K20: 江苏省连云港市灌云县 | L20: 13401998010 | M20: 本科 | N20: 土建 | O20: 扬州大学 | P20: 2001-12-31 | Q20: 股东 | R20: 干部 | S20: 群众 | T20: 陈苏宁 | U20: 陈苏宁 | V20: 管理创新研究室 | W20: 2025-12-26 16:53:21 | X20: 2026-03-23 14:37:07 | Y20: 已生效 | Z20: 南京南化建设有限公司 | AA20: 江苏省 南京市 六合区 大厂街道杨新路188号化建新一村 | AB20: 是 | AC20: 是 | AD20: 是 | AE20: 周小明 | AF20: 合同管理部 | AG20: 32D27451-2EC9-305E-8943-5A186C13BAF3 | AH20: 否 | AJ20: 1992004 | AK20: 在职
A21: 资产财务部 | B21: 杨志旺 | C21: 男 | D21: 320112197306100416 | E21: 业务主管 | F21: 1973-06 | G21: 52 | H21: 1991-07-01 | I21: 1991-07-01 | J21: 专业技术 | L21: 15952095170 | M21: 大专 | N21: 会计 | O21: 中央广播电视大学 | P21: 2006-07-01 | Q21: 股东 | R21: 干部 | S21: 群众 | T21: 陈苏宁 | U21: 陈苏宁 | V21: 管理创新研究室 | W21: 2025-12-26 16:53:21 | X21: 2026-03-20 17:30:05 | Y21: 已生效 | Z21: 南京南化建设有限公司 | AB21: 否 | AC21: 是 | AD21: 否 | AF21: 资产财务部 | AG21: 3E3C5E36-5053-4F95-061F-313731516458 | AH21: 否 | AJ21: 1991009 | AK21: 在职
A22: 公司领导 | B22: 甘继荣 | C22: 男 | D22: 510212196809080417 | E22: 董事长 | F22: 1968-09 | G22: 57 | H22: 1991-08-01 | I22: 1991-08-01 | J22: 经营管理 | L22: 13605154691 | M22: 本科 | N22: 化机 | O22: 重庆建筑工程学院 | P22: 1991-07-01 | Q22: 股东 | R22: 干部 | S22: 民盟盟员 | T22: 陈苏宁 | U22: 陈苏宁 | V22: 管理创新研究室 | W22: 2025-12-26 16:53:21 | X22: 2026-05-07 10:32:13 | Y22: 已生效 | Z22: 南京南化建设有限公司 | AB22: 否 | AC22: 是 | AD22: 否 | AF22: 公司领导 | AG22: 8C38B17D-9849-9632-5F61-AB00943D8F41 | AH22: 否 | AJ22: 1991002 | AK22: 在职
A23: 项目管理公司 | B23: 杨伟群 | C23: 男 | D23: 320112197104161659 | E23: 主要工种高级工 | F23: 1971-04 | G23: 54 | H23: 1990-12-01 | I23: 1990-12-01 | J23: 技能操作 | K23: 山东省临沂市郯城县 | L23: 18905156231 | M23: 高中 | N23: 钳工 | O23: 南化一中 | P23: 1989-07-01 | Q23: 股东 | R23: 工人 | S23: 群众 | T23: 陈苏宁 | U23: 陈苏宁 | V23: 管理创新研究室 | W23: 2025-12-26 16:53:21 | X23: 2026-03-23 14:37:12 | Y23: 已生效 | Z23: 南京南化建设有限公司 | AA23: 江苏省 南京市 六合区 | AB23: 是 | AC23: 是 | AD23: 是 | AF23: 合同管理部 | AG23: F32609BF-ACF7-DED0-CCF5-4C920B1F5663 | AH23: 否 | AJ23: 1990018 | AK23: 在职
A24: 资产财务部 | B24: 朱彬 | C24: 男 | D24: 321026197311017311 | E24: 副总师 | F24: 1973-11 | G24: 52 | H24: 1990-12-01 | I24: 1990-12-01 | J24: 经营管理 | L24: 13601406998 | M24: 大专 | O24: 南京工业大学 | P24: 1997-07-01 | Q24: 股东 | R24: 干部 | S24: 党员 | T24: 陈苏宁 | U24: 陈苏宁 | V24: 管理创新研究室 | W24: 2025-12-26 16:53:21 | X24: 2026-03-20 17:30:31 | Y24: 已生效 | Z24: 南京南化建设有限公司 | AA24: 江苏省 南京市 雨花台区 翠岛花城 | AB24: 是 | AC24: 是 | AD24: 否 | AE24: 王勇 | AF24: 资产财务部 | AG24: 39B82F4C-2A89-C9E1-5061-4738002D74EE | AH24: 否 | AJ24: 1990020 | AK24: 在职
A25: 待岗人员 | B25: 王前高 | C25: 男 | D25: 320112197103170019 | E25: 副队长 | F25: 1971-03 | G25: 54 | H25: 1990-12-01 | I25: 1990-12-01 | J25: 技能操作 | K25: 江苏省宿迁市泗洪县 | L25: 13951896779 | M25: 大专 | N25: 钳工 | O25: 中央广播大学 | P25: 2005-07-01 | Q25: 股东 | R25: 工人 | S25: 党员 | T25: 陈苏宁 | U25: 陈苏宁 | V25: 管理创新研究室 | W25: 2025-12-26 16:53:21 | X25: 2026-03-23 14:37:12 | Y25: 已生效 | Z25: 南京南化建设有限公司 | AA25: 江苏省 南京市 六合区 周洼新村3-104 | AB25: 是 | AC25: 是 | AD25: 是 | AF25: 安装三分公司 | AG25: 092BC8E1-D933-7D2D-5317-205266187734 | AH25: 否 | AJ25: 1990012 | AK25: 在职
A26: 待岗人员 | B26: 沙永忠 | C26: 男 | D26: 320112197202191659 | E26: 业务主办B | F26: 1972-02 | G26: 53 | H26: 1990-12-01 | I26: 1990-12-01 | J26: 专业技术 | K26: 江苏省南京市六合区 | L26: 13951737938 | M26: 高中 | N26: 材料员 | P26: 1970-01-01 | Q26: 股东 | R26: 干部 | S26: 群众 | T26: 陈苏宁 | U26: 陈苏宁 | V26: 管理创新研究室 | W26: 2025-12-26 16:53:21 | X26: 2026-03-23 14:37:13 | Y26: 已生效 | Z26: 南京南化建设有限公司 | AA26: 江苏省 南京市 六合区 化学工业园区扬子十一村1幢106室 | AB26: 是 | AC26: 是 | AD26: 是 | AF26: 安装三分公司 | AG26: 3B667C7F-48E9-2C5E-D873-7F9E4570993C | AH26: 否 | AJ26: 1990009 | AK26: 在职
A27: 综合办公室 | B27: 严贵宁 | C27: 男 | D27: 320112197002060013 | E27: 辅助工种高级工 | F27: 1970-02 | G27: 55 | H27: 1990-12-01 | I27: 1990-12-01 | J27: 技能操作 | K27: 江苏省徐州市 | L27: 13915954273 | M27: 初中 | N27: 驾驶员 | P27: 1987-07-01 | Q27: 股东 | R27: 工人 | S27: 群众 | T27: 陈苏宁 | U27: 陈苏宁 | V27: 管理创新研究室 | W27: 2025-12-26 16:53:21 | X27: 2026-03-23 14:37:13 | Y27: 已生效 | Z27: 南京南化建设有限公司 | AA27: 江苏省 南京市 六合区 大厂街道新华五村 | AB27: 是 | AC27: 是 | AD27: 是 | AF27: 经理办公室 | AG27: 8E6CC736-8462-E4EA-7CF7-7B1CB069A4FC | AH27: 否 | AJ27: 1990017 | AK27: 在职
A28: 公司领导 | B28: 方向前 | C28: 男 | D28: 36233019701216461X | E28: 副总经理 | F28: 1970-12 | G28: 55 | H28: 1992-08-01 | I28: 1992-08-01 | J28: 经营管理 | L28: 13062588684 | M28: 大专 | N28: 材料员 | O28: 南京建筑工程学院 | P28: 1992-07-01 | Q28: 股东 | R28: 干部 | S28: 群众 | T28: 陈苏宁 | U28: 陈苏宁 | V28: 管理创新研究室 | W28: 2025-12-26 16:53:21 | X28: 2026-03-20 17:30:53 | Y28: 已生效 | Z28: 南京南化建设有限公司 | AB28: 否 | AC28: 是 | AD28: 否 | AF28: 公司领导 | AG28: 834C4992-ACDB-3C57-E6F0-EBB91F06396E | AH28: 否 | AJ28: 1992003 | AK28: 在职
A29: 公司领导 | B29: 王勇 | C29: 男 | D29: 320112197210230435 | E29: 副总经理 | F29: 1972-10 | G29: 53 | H29: 1991-07-01 | I29: 1991-07-01 | J29: 经营管理 | L29: 13951908508 | M29: 大专 | N29: 会计 | O29: 华中科技大学 | P29: 2022-05-18 | Q29: 股东 | R29: 干部 | S29: 群众 | T29: 陈苏宁 | U29: 陈苏宁 | V29: 管理创新研究室 | W29: 2025-12-26 16:53:21 | X29: 2026-05-07 10:32:13 | Y29: 已生效 | Z29: 南京南化建设有限公司 | AB29: 否 | AC29: 是 | AD29: 否 | AF29: 公司领导 | AG29: 1DE12F17-BBEC-4117-A4BC-019DC05C3AEB | AH29: 否 | AJ29: 1991008 | AK29: 在职
A30: 资产财务部 | B30: 雷鸣 | C30: 男 | D30: 320112197205210413 | E30: 业务主管 | F30: 1972-05 | G30: 53 | H30: 1991-07-01 | I30: 1991-07-01 | J30: 专业技术 | L30: 13401991310 | M30: 中专 | N30: 会计 | P30: 2020-01-14 | Q30: 股东 | R30: 干部 | S30: 群众 | T30: 陈苏宁 | U30: 陈苏宁 | V30: 管理创新研究室 | W30: 2025-12-26 16:53:21 | X30: 2026-03-20 17:31:05 | Y30: 已生效 | Z30: 南京南化建设有限公司 | AA30: 江苏省 南京市 六合区 芳庭潘园 | AB30: 是 | AC30: 是 | AD30: 是 | AF30: 资产财务部 | AG30: 669207DF-780A-5276-D3BA-EC9B46D90856 | AH30: 否 | AJ30: 1991005 | AK30: 在职
A31: 资产财务部 | B31: 周媛 | C31: 女 | D31: 320112197108221620 | E31: 业务主管 | F31: 1971-08 | G31: 54 | H31: 1992-12-01 | I31: 1992-12-01 | J31: 专业技术 | L31: 15161490239 | M31: 大专 | N31: 会计 | O31: 江苏省自学考试中心 | P31: 1992-12-01 | Q31: 股东 | R31: 干部 | S31: 群众 | T31: 陈苏宁 | U31: 陈苏宁 | V31: 管理创新研究室 | W31: 2025-12-26 16:53:21 | X31: 2026-03-20 17:31:14 | Y31: 已生效 | Z31: 南京南化建设有限公司 | AB31: 否 | AC31: 是 | AD31: 否 | AF31: 资产财务部 | AG31: E6D577B7-BA23-ADF9-0A33-83C70C504EA1 | AH31: 否 | AJ31: 1992007 | AK31: 在职
A32: 资产财务部 | B32: 胡锦刚 | C32: 男 | D32: 511027197006273038 | E32: 主管工程师 | F32: 1970-06 | G32: 55 | H32: 1991-08-01 | I32: 1991-08-01 | J32: 专业技术 | L32: 15105151142 | M32: 大专 | N32: 会计 | O32: 郑州航空工业管理学院 | P32: 1991-07-01 | Q32: 股东 | R32: 干部 | S32: 群众 | T32: 陈苏宁 | U32: 陈苏宁 | V32: 管理创新研究室 | W32: 2025-12-26 16:53:21 | X32: 2026-03-20 17:31:18 | Y32: 已生效 | Z32: 南京南化建设有限公司 | AA32: 江苏省 南京市 六合区 草芳新苑55栋 | AB32: 是 | AC32: 是 | AD32: 否 | AF32: 资产财务部 | AG32: F5757B02-AA63-6A61-6A8E-BA48D8409EBF | AH32: 否 | AJ32: 1991004 | AK32: 在职
A33: 公司领导 | B33: 周小明 | C33: 男 | D33: 210211196812205850 | E33: 副总经理 | F33: 1968-12 | G33: 57 | H33: 1990-08-01 | I33: 1990-08-01 | J33: 经营管理 | K33: 江苏省扬州市仪征市 | L33: 13905163029 | M33: 本科 | N33: 土建 | O33: 大连理工大学 | P33: 1990-07-01 | Q33: 股东 | R33: 干部 | S33: 党员 | T33: 陈苏宁 | U33: 陈苏宁 | V33: 管理创新研究室 | W33: 2025-12-26 16:53:21 | X33: 2026-03-20 17:31:27 | Y33: 已生效 | Z33: 南京南化建设有限公司 | AB33: 否 | AC33: 是 | AD33: 否 | AF33: 公司领导 | AG33: 9DA4B905-0984-619F-6EF0-65FB925FFAE0 | AH33: 否 | AJ33: 1990019 | AK33: 在职
A34: 技术质量部 | B34: 李文娟 | C34: 女 | D34: 320923197410262426 | E34: 主管工程师 | F34: 1974-10 | G34: 51 | H34: 1995-08-01 | I34: 1995-08-01 | J34: 专业技术 | K34: 江苏省盐城市阜宁县 | L34: 13770828162 | M34: 大专 | N34: 化机 | O34: 南京化工大学 | P34: 1995-07-01 | Q34: 股东 | R34: 干部 | S34: 群众 | T34: 陈苏宁 | U34: 陈苏宁 | V34: 管理创新研究室 | W34: 2025-12-26 16:53:20 | X34: 2026-03-20 17:31:36 | Y34: 已生效 | Z34: 南京南化建设有限公司 | AA34: 江苏省 南京市 六合区 大厂街道福基旭东新城18幢 | AB34: 是 | AC34: 是 | AD34: 是 | AF34: 技术质量部 | AG34: 978EF8FD-5467-B2C2-F294-E4C56D620B0C | AH34: 否 | AJ34: 1995007 | AK34: 在职
A35: 待岗人员 | B35: 邱关波 | C35: 男 | D35: 320112197309081652 | E35: 主要工种高级工 | F35: 1973-09 | G35: 52 | H35: 1993-09-01 | I35: 1993-09-01 | J35: 技能操作 | K35: 江苏省南京市六合区 | L35: 15380754020 | M35: 技校 | N35: 安全员 | P35: 1993-07-01 | Q35: 股东 | R35: 工人 | S35: 群众 | T35: 陈苏宁 | U35: 陈苏宁 | V35: 管理创新研究室 | W35: 2025-12-26 16:53:20 | X35: 2026-05-07 10:32:13 | Y35: 已生效 | Z35: 南京南化建设有限公司 | AB35: 否 | AC35: 是 | AD35: 否 | AF35: 人力资源部 | AG35: CA6E1EB1-CDBF-AA83-4EE4-6CE164620C10 | AH35: 否 | AJ35: 1993010 | AK35: 在职
A36: 信息化中心 | B36: 蔡雷萌 | C36: 男 | D36: 320705197403302019 | E36: 副总师 | F36: 1974-03 | G36: 51 | H36: 1995-08-01 | I36: 1995-08-01 | J36: 经营管理 | K36: 北京市 | L36: 18626455696 | M36: 大专 | N36: 电气 | O36: 连云港化工高等专业学校 | P36: 1995-07-01 | Q36: 股东 | R36: 干部 | S36: 群众 | T36: 陈苏宁 | U36: 陈苏宁 | V36: 管理创新研究室 | W36: 2025-12-26 16:53:20 | X36: 2026-03-23 14:37:15 | Y36: 已生效 | Z36: 南京南化建设有限公司 | AA36: 江苏省 南京市 江宁区 东山街道萃文路99号明月花园25A304 | AB36: 是 | AC36: 是 | AD36: 是 | AE36: 郭晓瑙 | AF36: 马来西亚分公司（国外） | AG36: A3D85AC0-A6EF-49D7-BED1-FA3634C42CED | AH36: 否 | AJ36: 1995001 | AK36: 在职
A37: 资产财务部 | B37: 张学军 | C37: 男 | D37: 320112197306170414 | E37: 中层正职级(一类) | F37: 1973-06 | G37: 52 | H37: 1993-08-01 | I37: 1993-08-01 | J37: 经营管理 | L37: 15151888150 | M37: 大专 | O37: 江苏省自学考试中心 | P37: 2020-01-10 | Q37: 股东 | R37: 干部 | S37: 群众 | T37: 陈苏宁 | U37: 陈苏宁 | V37: 管理创新研究室 | W37: 2025-12-26 16:53:20 | X37: 2026-03-20 17:31:54 | Y37: 已生效 | Z37: 南京南化建设有限公司 | AA37: 江苏省 南京市 玄武区 罗汉巷小区 | AB37: 是 | AC37: 是 | AD37: 否 | AE37: 王勇 | AF37: 资产财务部 | AG37: 7A96F400-F9B9-269E-1098-BBF065B00554 | AH37: 否 | AJ37: 1993014 | AK37: 在职
A38: 物资部 | B38: 冯艳兰 | C38: 女 | D38: 320112197511110445 | E38: 业务主管 | F38: 1975-11 | G38: 50 | H38: 1994-08-01 | I38: 1994-08-01 | J38: 专业技术 | K38: 江苏省淮安市涟水县 | L38: 18913320625 | M38: 中专 | N38: 电气 | O38: 扬州化工学校 | P38: 1994-06-30 | Q38: 股东 | R38: 干部 | S38: 群众 | T38: 陈苏宁 | U38: 陈苏宁 | V38: 管理创新研究室 | W38: 2025-12-26 16:53:20 | X38: 2026-03-20 17:32:03 | Y38: 已生效 | Z38: 南京南化建设有限公司 | AA38: 江苏省 南京市 浦口区 盘金华府21-403 | AB38: 是 | AC38: 是 | AD38: 是 | AF38: 物资部 | AG38: 9BB2BAFB-24AF-D0A3-4221-A99467C9BD05 | AH38: 否 | AJ38: 1994003 | AK38: 在职
A39: 项目管理公司 | B39: 尹八一 | C39: 男 | D39: 321025197308012011 | E39: 中层正职(一类) | F39: 1973-08 | G39: 52 | H39: 1994-08-01 | I39: 1994-08-01 | J39: 经营管理 | K39: 江苏省泰州市泰兴市 | L39: 15850710523 | M39: 本科 | N39: 化机 | O39: 江苏石油化工学院 | P39: 1994-07-01 | Q39: 股东 | R39: 干部 | S39: 群众 | T39: 陈苏宁 | U39: 陈苏宁 | V39: 管理创新研究室 | W39: 2025-12-26 16:53:20 | X39: 2026-03-23 14:37:16 | Y39: 已生效 | Z39: 南京南化建设有限公司 | AA39: 江苏省 南京市 浦口区 | AB39: 是 | AC39: 是 | AD39: 是 | AE39: 周小明 | AF39: 合同管理部 | AG39: AD351C7F-2839-E655-4196-71D266477BD2 | AH39: 否 | AJ39: 1994008 | AK39: 在职
A40: 综合办公室 | B40: 郭凤霞 | C40: 女 | D40: 32011119750103442X | E40: 业务主管 | F40: 1975-01 | G40: 50 | H40: 1994-08-01 | I40: 1994-08-01 | J40: 专业技术 | K40: 江苏省南京市浦口区 | L40: 15951790494 | M40: 本科 | N40: 其他 | O40: 苏州大学 | P40: 2004-12-30 | Q40: 股东 | R40: 干部 | S40: 群众 | T40: 陈苏宁 | U40: 陈苏宁 | V40: 管理创新研究室 | W40: 2025-12-26 16:53:20 | X40: 2026-03-23 14:37:18 | Y40: 已生效 | Z40: 南京南化建设有限公司 | AA40: 江苏省 南京市 浦口区 沿江街道新城·香溢紫郡花园北区 | AB40: 是 | AC40: 是 | AD40: 是 | AF40: 经理办公室 | AG40: 0F274E61-37D9-6ACE-47E1-86100EA6D436 | AH40: 否 | AJ40: 1994004 | AK40: 在职
...
